// To handle the error we use try catch


try {
  let a= 5;
  let b = a+x;
 console.log(b)
} catch (err) {
    console.log("Error occured :",err.message)
}